Workbook

Sheet old
A1: 4 | B1: 2 | C1: 3 | D1: 4 | E1: 5 | F1: 6 | G1: 7 | H1: 8 | I1: 9 | J1: 10 | K1: 11 | L1: 12 | M1: 13 | N1: 14 | O1: 15 | P1: 16 | Q1: 17 | R1: 18 | S1: 19 | T1: 20 | U1: 21 | V1: 22 | W1: 23 | X1: 24 | Y1: 25 | Z1: 26 | AA1: 27 | AB1: 28 | AC1: 29 | AD1: 30 | AE1: 31 | AF1: 32 | AG1: 33 | AH1: 34 | AI1: 35 | AJ1: 36 | AK1: 37 | AL1: 38 | AM1: 39 | AN1: 40 | AO1: 41 | AP1: 42 | AQ1: 43 | AR1: 44 | AS1: 45 | AT1: 46 | AU1: 47 | AV1: 48 | AW1: 49
A2: inn | B2: id | C2: name | D2: inn | E2: ogrn | F2: name_light | G2: date_register | H2: working_years | I2: napka | J2: founder | K2: director | L2: adress | M2: capital | N2: agent | O2: raiting_get_a | P2: cess | Q2: raiting_get_c | R2: income2020 | S2: income2021 | T2: income2022 | U2: income2023 | V2: income2024 | W2: cost2020 | X2: cost2021 | Y2: cost2022 | Z2: cost2023 | AA2: cost2024 | AB2: profit2020 | AC2: profit2021 | AD2: profit2022 | AE2: profit2023 | AF2: profit2024 | AG2: invest2020 | AH2: invest2021 | AI2: invest2022 | AJ2: invest2023 | AK2: invest2024 | AL2: receivable2020 | AM2: receivable2021 | AN2: receivable2022 | AO2: receivable2023 | AP2: receivable2024 | AQ2: loan | AR2: grow_income_2019_2023 | AS2: risk_fssp | AT2: site | AU2: logo | AV2: temp_grow_2019_2023 | AW2: description
A3: 7735174895 | B3: 24 | C3: Общество с ограниченной ответственностью Профессиональная коллекторская организация «Гольфстрим-Р» | D3: 7735174895 | E3: 1187746489204 | F3: ООО ПКО «Гольфстрим-Р» | G3: 43238 | H3: 6 | I3: Нет | J3: Топкаев Роберт Анатольевич, Сирота Георгий Витальевич, Литвак Игорь Маркович | K3: Побожая Ирина Валерьевна | L3: 125009, Москва г, пер Большой Кисловский, д. 4, стр. 3, этаж 1, помещ. 22 | M3: 10010 | R3: 122430 | S3: 432052 | T3: 793479 | U3: 829409 | W3: 85562 | X3: 332275 | Y3: 614066 | Z3: 699868 | AB3: 85562 | AC3: 8256 | AD3: 11659 | AE3: -40805 | AG3: 0 | AH3: 447519 | AI3: 516670 | AJ3: 416339 | AL3: 241035 | AM3: 57166 | AN3: 88319 | AO3: 76206 | AS3: 0 | AT3: golfstream0r.ru | AU3: image344 | AW3: ООО ПКО «Гольфстрим-Р» зарегистрировано по адресу: 125009, Москва г, пер Большой Кисловский, д. 4, стр. 3, этаж 1, помещ. 22. Генеральным директором является Побожая Ирина Валерьевна.
A4: 5407980426 | B4: 231 | C4: Общество с ограниченной ответственностью «ИнтИнвест» | D4: 5407980426 | E4: 1215400000254 | F4: ООО «ИнтИнвест» | G4: 44209 | H4: 4 | I4: Нет | J4: Перехожев Алексей Александрович | K4: Перехожев Алексей Александрович | L4: Новосибирская обл., г.о. город Новосибирск, г. Новосибирск, ул. Фабричная, д. 4, ОФИС 412, 630007 | M4: 26.665 | R4: 0 | S4: 64318 | T4: 90885 | U4: 4384 | W4: 0 | X4: 44387 | Y4: 73283 | Z4: 34379 | AB4: 0 | AC4: 3719 | AD4: 545 | AE4: -32934 | AG4: 0 | AH4: 90871 | AI4: 34191 | AJ4: 4080 | AL4: 0 | AM4: 71255 | AN4: 55608 | AO4: 1076 | AS4: Высокий | AT4: intcollect.ru | AU4: image1001 | AW4: ООО «ИнтИнвест» зарегистрировано по адресу: Новосибирская обл., г.о. город Новосибирск, г. Новосибирск, ул. Фабричная, д. 4, ОФИС 412, 630007. Генеральным директором является Перехожев Алексей Александрович. ФССП присвоил Высокий уровень риска для данного ПКО.
A5: 9723118667 | B5: 390 | C5: Общество с ограниченной ответственностью «Инфорс-Право» | D5: 9723118667 | E5: 1217700289377 | F5: ООО «Инфорс-Право» | G5: 44365 | H5: 3 | I5: Нет | J5: Варлыгин Евгений Валерьевич | K5: Варлыгин Евгений Валерьевич | L5: 109341, Москва г, ул Люблинская, 151, Этаж 2 Помещ. 201 | M5: 10 | R5: 0 | S5: 0 | T5: 2400 | U5: 4800 | W5: 0 | X5: 133 | Y5: 48 | Z5: 82 | AB5: 0 | AC5: -2399 | AD5: -1413 | AE5: 1361 | AG5: 0 | AH5: 0 | AI5: 0 | AJ5: 0 | AL5: 0 | AM5: 21 | AN5: 673 | AO5: 1875 | AS5: Низкий | AT5: enfpv.ru | AU5: image1001 | AW5: ООО «Инфорс-Право» зарегистрировано по адресу: 109341, Москва г, ул Люблинская, 151, Этаж 2 Помещ. 201. Генеральным директором является Варлыгин Евгений Валерьевич. ФССП присвоил Низкий уровень риска для данного ПКО.
A6: 7813484544 | B6: 405 | C6: Общество с ограниченной ответственностью «Профессиональная коллекторская организация «Юридическая безопасность бизнеса» | D6: 7813484544 | E6: 1107847355000 | F6: ООО «ПКО «ЮББ» | G6: 40473 | H6: 14 | I6: Нет | J6: Лаврова Ольга Игоревна | K6: Семёнов Максим Валерьевич | L6: 197110, Город Санкт-Петербург, пр-кт Левашовский, дом 12, литер А, комната 356 | M6: 9000 | R6: 82350 | S6: 4288 | T6: 2354 | U6: 3988 | W6: 77443 | X6: 737 | Y6: 956 | Z6: 57 | AB6: 77443 | AC6: 1265 | AD6: 63 | AE6: 7 | AG6: 35252 | AH6: 30718 | AI6: 29280 | AJ6: 26237 | AL6: 163 | AM6: 125 | AN6: 102 | AO6: 119 | AS6: Низкий | AT6: ubbltd.ru | AU6: image221 | AW6: ООО «ПКО «ЮББ» зарегистрировано по адресу: 197110, Город Санкт-Петербург, пр-кт Левашовский, дом 12, литер А, комната 356. Генеральным директором является Семёнов Максим Валерьевич. ФССП присвоил Низкий уровень риска для данного ПКО.
A7: 6686116656 | B7: 421 | C7: Общество с ограниченной ответственностью «РЕГОЛА» | D7: 6686116656 | E7: 1196658043900 | F7: ООО «РЕГОЛА» | G7: 43637 | H7: 5 | I7: Нет | J7: Прокопьев Александр Валерьевич | K7: Прокопьев Александр Валерьевич | L7: 620057, Свердловская обл, г Екатеринбург, ул Фрезеровщиков, 78, 71 | M7: 20 | R7: 26382 | S7: 59707 | T7: 2311 | U7: 2810 | W7: 337 | X7: 7122 | Y7: 1565 | Z7: 2441 | AB7: 337 | AC7: 52523 | AD7: 694 | AE7: 341 | AG7: 0 | AH7: 0 | AI7: 0 | AJ7: 0 | AL7: 25339 | AM7: 82920 | AN7: 82441 | AO7: 83054 | AS7: Низкий | AT7: regolaek.ru | AU7: image1001 | AW7: ООО «РЕГОЛА» зарегистрировано по адресу: 620057, Свердловская обл, г Екатеринбург, ул Фрезеровщиков, 78, 71. Генеральным директором является Прокопьев Александр Валерьевич. ФССП присвоил Низкий уровень риска для данного ПКО.
A8: 7722466428 | B8: 425 | C8: Общество с ограниченной ответственностью «Кредо Финанс» | D8: 7722466428 | E8: 1187746783355 | F8: ООО «Кредо Финанс» | G8: 43341 | H8: 6 | I8: Нет | J8: Федюков Владимир Константинович | K8: Федюков Владимир Константинович | L8: 123290, Москва г, Ермакова Роща ул, дом 7Б, строение 6, офис 3/9 | M8: 250 | R8: 1761 | S8: 2955 | T8: 3220 | U8: 2381 | W8: 1482 | X8: 1770 | Y8: 2948 | Z8: 1712 | AB8: 1482 | AC8: 1071 | AD8: 182 | AE8: 622 | AG8: 0 | AH8: 0 | AI8: 0 | AJ8: 0 | AL8: 18460 | AM8: 16323 | AN8: 16636 | AO8: 20075 | AS8: Высокий | AT8: crfinance.ru | AU8: image1001 | AW8: ООО «Кредо Финанс» зарегистрировано по адресу: 123290, Москва г, Ермакова Роща ул, дом 7Б, строение 6, офис 3/9. Генеральным директором является Федюков Владимир Константинович. ФССП присвоил Высокий уровень риска для данного ПКО.
A9: 3702724465 | B9: 456 | C9: Общество с ограниченной ответственностью «Компания региональный Долговой Центр» | D9: 3702724465 | E9: 1143702006931 | F9: ООО «КРДЦ» | G9: 45603 | H9: 0 | I9: Нет | L9: 153013, Ивановская обл, г Иваново, ул Панина, 16а Дом | M9: 10 | R9: 9778 | S9: 2960 | T9: 146 | U9: 371 | W9: 9338 | X9: 4083 | Y9: 645 | Z9: 11824 | AB9: 9338 | AC9: -1174 | AD9: -503 | AE9: -11461 | AG9: 33 | AH9: 0 | AI9: 0 | AJ9: 0 | AL9: 12392 | AM9: 11766 | AN9: 11392 | AO9: 234 | AS9: Низкий | AT9: regiondolg.ru | AU9: image274 | AW9: ООО «КРДЦ» зарегистрировано по адресу: 153013, Ивановская обл, г Иваново, ул Панина, 16а Дом
A10: 3443147600 | B10: 459 | C10: Общество с ограниченной ответственностью «ПРОФЕССИОНАЛЬНАЯ КОЛЛЕКТОРСКАЯ ОРГАНИЗАЦИЯ «АРРИАРС» | D10: 3443147600 | E10: 1213400010042 | F10: ООО «ПКО «АРРИАРС» | G10: 44483 | H10: 3 | I10: Нет | J10: Казаков Олег Олегович, Сабиров Салават Рифович | K10: Чередник Вадим Викторович | L10: Волгоградская обл, историческая, д. № 181 | M10: 10 | R10: 0 | S10: 0 | T10: 13467 | U10: 269 | W10: 0 | X10: 0 | Y10: 11890 | Z10: 79 | AB10: 0 | AC10: 0 | AD10: 761 | AE10: 174 | AG10: 0 | AH10: 0 | AI10: 0 | AJ10: 0 | AL10: 0 | AM10: 587 | AN10: 9341 | AO10: 14822 | AS10: Низкий | AT10: arriars.ru | AU10: image1001 | AW10: ООО «ПКО «АРРИАРС» зарегистрировано по адресу: Волгоградская обл, историческая, д. № 181. Генеральным директором является Чередник Вадим Викторович. ФССП присвоил Низкий уровень риска для данного ПКО.
A11: 7810450515 | B11: 467 | C11: Общество с ограниченной ответственностью «Группа компаний «Юрфининвест» | D11: 7810450515 | E11: 1137847308642 | F11: ООО «ГК «Юрфининвест» | G11: 45666 | H11: 0 | I11: Нет | L11: 115088, Москва г, 2-Я Машиностроения ул, дом 17, строение 1, этаж 2, помещение I, комната 63, офис 60 | M11: 10 | R11: 829 | S11: 18783 | T11: 11100 | U11: 12 | W11: 1114 | X11: 1673 | Y11: 17057 | Z11: 80 | AB11: 1114 | AC11: 16556 | AD11: -5957 | AE11: -69 | AG11: 0 | AH11: 0 | AI11: 0 | AJ11: 0 | AL11: 16854 | AM11: 28285 | AN11: 20661 | AO11: 20670 | AS11: 0 | AT11: gk0ufi.ru | AU11: image1001 | AW11: ООО «ГК «Юрфининвест» зарегистрировано по адресу: 115088, Москва г, 2-Я Машиностроения ул, дом 17, строение 1, этаж 2, помещение I, комната 63, офис 60
A12: 4027143645 | B12: 470 | C12: Общество с ограниченной ответственностью Профессиональная коллекторская организация «РУСФИНАЛЬЯНС» | D12: 4027143645 | E12: 1204000005263 | F12: ООО ПКО «РУСФИНАЛЬЯНС» | G12: 44028 | H12: 4 | I12: Нет | J12: Зигель Сильвио | K12: Карасев Владимир Николаевич | L12: 248002, Калужская область, г. Калуга, ул. Болдина, здание 71, офис 213 | M12: 20 | R12: 50 | S12: 10116 | T12: 29 | U12: 4 | W12: 61 | X12: 10577 | Y12: 1091 | Z12: 113 | AB12: 61 | AC12: -468 | AD12: -1065 | AE12: -109 | AG12: 0 | AH12: 0 | AI12: 0 | AJ12: 0 | AL12: 310 | AM12: 17017 | AN12: 20062 | AO12: 20046 | AS12: Низкий | AT12: rus0finalyans.ru | AU12: image323 | AW12: ООО ПКО «РУСФИНАЛЬЯНС» зарегистрировано по адресу: 248002, Калужская область, г. Калуга, ул. Болдина, здание 71, офис 213. Генеральным директором является Карасев Владимир Николаевич. ФССП присвоил Низкий уровень риска для данного ПКО.
A13: 7736602060 | B13: 474 | C13: Общество с ограниченной ответственностью «Центр ЮСБ-М» | D13: 7736602060 | E13: 1097746188924 | F13: ООО «Центр ЮСБ-М» | G13: 45365 | H13: 1 | I13: Нет | L13: 117335, Москва г, Вавилова ул, дом 79, корпус 1, офис 4 | M13: 100 | R13: 77858 | S13: 94870 | T13: 121679 | U13: 64790 | W13: 1579 | X13: 40194 | Y13: 55682 | Z13: 32250 | AB13: 1579 | AC13: 50381 | AD13: 60627 | AE13: 30850 | AG13: 37035 | AH13: 38095 | AI13: 46000 | AJ13: 43500 | AL13: 8413 | AM13: 10720 | AN13: 8275 | AO13: 122 | AS13: Низкий | AT13: usb0m.ru | AU13: image1001 | AW13: ООО «Центр ЮСБ-М» зарегистрировано по адресу: 117335, Москва г, Вавилова ул, дом 79, корпус 1, офис 4
A14: 7717777530 | B14: 477 | C14: Общество с ограниченной ответственностью «Прайм Коллекшен» | D14: 7717777530 | E14: 1147746200062 | F14: ООО «Прайм Коллекшен» | G14: 45485 | H14: 0 | I14: Нет | L14: Москва г, ш.Дмитровское, д.100, стр.2ПОМ.4506, кв.05, 127247 | M14: 12.5 | R14: 17644 | S14: 16208 | T14: 15525 | U14: 0 | W14: 9894 | X14: 8607 | Y14: 6073 | Z14: 0 | AB14: 9894 | AC14: 7070 | AD14: 9018 | AE14: 0 | AG14: 0 | AH14: 0 | AI14: 0 | AJ14: 0 | AL14: 11129 | AM14: 18509 | AN14: 26030 | AO14: 0 | AS14: 0 | AT14: primecollection.ru | AU14: image1001 | AW14: ООО «Прайм Коллекшен» зарегистрировано по адресу: Москва г, ш.Дмитровское, д.100, стр.2ПОМ.4506, кв.05, 127247
A15: 5038126322 | B15: 481 | C15: Общество с ограниченной ответственностью «Профессиональное коллекторское бюро» | D15: 5038126322 | E15: 1175050002357 | F15: ООО «Профессиональное Коллекторское Бюро» | G15: 42809 | H15: 8 | I15: Нет | J15: Ганелин Владислав Дмитриевич, Штрафов | K15: Ганелин Владислав Дмитриевич | L15: 143404, Московская обл, г.о. Красногорск, г Красногорск, ул Парковая, д. 1, кв. эт/пом цоколь/5 | M15: 11710 | R15: 266 | S15: 0 | T15: 0 | U15: 0 | W15: 11 | X15: 0 | Y15: 0 | Z15: 0 | AB15: 11 | AC15: 0 | AD15: 0 | AE15: 0 | AG15: 44001 | AH15: 0 | AI15: 0 | AJ15: 0 | AL15: 74180 | AM15: 0 | AN15: 0 | AO15: 0 | AS15: Низкий | AT15: prof0coll.ru | AU15: image1001 | AW15: ООО «Профессиональное Коллекторское Бюро» зарегистрировано по адресу: 143404, Московская обл, г.о. Красногорск, г Красногорск, ул Парковая, д. 1, кв. эт/пом цоколь/5. Генеральным директором является Ганелин Владислав Дмитриевич. ФССП присвоил Низкий уровень риска для данного ПКО.
A16: 2130218594 | B16: 486 | C16: Акционерное общество «Профессиональная коллекторская организация «Инвест Групп» | D16: 2130218594 | E16: 1202100003665 | F16: АО «Профессиональная коллекторская организация «Инвест Групп» | G16: 45425 | H16: 0 | I16: Нет | L16: 198206, Город Санкт-Петербург, вн.тер. г. Муниципальный Округ Сосновая Поляна, ш Петергофское, дом 73, литера Т, помещение 1-Н, офис 17/4 РАБОЧЕЕ МЕСТО 3 | M16: 10 | R16: 0 | S16: 0 | T16: 0 | U16: 0 | W16: 0 | X16: 0 | Y16: 0 | Z16: 71 | AB16: 0 | AC16: 0 | AD16: 0 | AE16: -73 | AG16: 0 | AH16: 9000 | AI16: 9000 | AJ16: 10979 | AL16: 0 | AM16: 0 | AN16: 0 | AO16: 1442 | AS16: Низкий | AT16: invest0gr.ru.com | AU16: image1001 | AW16: АО «Профессиональная коллекторская организация «Инвест Групп» зарегистрировано по адресу: 198206, Город Санкт-Петербург, вн.тер. г. Муниципальный Округ Сосновая Поляна, ш Петергофское, дом 73, литера Т, помещение 1-Н, офис 17/4 РАБОЧЕЕ МЕСТО 3
A17: 7813286084 | B17: 490 | C17: Общество с ограниченной ответственностью «Центр АвтоФинансовых технологий» | D17: 7813286084 | E17: 1177847277255 | F17: ООО «ЦАФТ» | G17: 45378 | H17: 1 | I17: Нет | L17: 196084, Санкт-Петербург г, ул Черниговская, д. 8, литера А, помещ. 29Н, 81Н | M17: 10000 | R17: 3626480 | S17: 4020218 | T17: 8094908 | U17: 41399 | W17: 2862766 | X17: 3342565 | Y17: 7932887 | Z17: 54536 | AB17: 2862766 | AC17: 23848 | AD17: -13354 | AE17: -12005 | AG17: 5159588 | AH17: 7739045 | AI17: 12388 | AJ17: 5221 | AL17: 63069 | AM17: 125557 | AN17: 10150 | AO17: 248 | AS17: Низкий | AT17: caftauto.ru | AU17: image1001 | AW17: ООО «ЦАФТ» зарегистрировано по адресу: 196084, Санкт-Петербург г, ул Черниговская, д. 8, литера А, помещ. 29Н, 81Н
A18: 4101167155 | B18: 510 | C18: Общество с ограниченной ответственностью Профессиональная коллекторская организация «Правовой консалтинг» | D18: 4101167155 | E18: 1144101035924 | F18: ООО ПКО «Правовой консалтинг» | G18: 42001 | H18: 10 | I18: Нет | J18: Ван Чунвэнь | K18: Ломов Иван Викторович | L18: 683002, г.Петропавловск-Камчатский, ул.Виталия Кручины, д.6, кв.36 | M18: 10 | R18: 0 | S18: 0 | T18: 0 | U18: 0 | W18: 0 | X18: 0 | Y18: 0 | Z18: 0 | AB18: 0 | AC18: 0 | AD18: 0 | AE18: 0 | AG18: 0 | AH18: 0 | AI18: 0 | AJ18: 0 | AL18: 0 | AM18: 0 | AN18: 0 | AO18: 0 | AS18: Низкий | AT18: consult41.ru | AU18: image1001 | AW18: ООО ПКО «Правовой консалтинг» зарегистрировано по адресу: 683002, г.Петропавловск-Камчатский, ул.Виталия Кручины, д.6, кв.36. Генеральным директором является Ломов Иван Викторович. ФССП присвоил Низкий уровень риска для данного ПКО.
A19: 9705066046 | B19: 535 | C19: Общество с ограниченной ответственностью «КВЕСТОР» | D19: 9705066046 | E19: 1167746430125 | F19: ООО «КВЕСТОР» | G19: 45409 | H19: 0 | I19: Нет | J19: Филатов Данил Анатольевич | K19: Глаголев Роман Анатольевич | L19: 125252, Москва г, вн.тер.г. муниципальный округ Хорошевский, ул Авиаконструктора Микояна, д. 12, помещ. Б | M19: 8010 | R19: 33695 | S19: 504039 | T19: 201666 | U19: 155398 | W19: 28028 | X19: 341851 | Y19: 187346 | Z19: 381784 | AB19: 28028 | AC19: 128361 | AD19: 2886 | AE19: -226643 | AG19: 0 | AH19: 10 | AI19: 10 | AJ19: 10 | AL19: 259754 | AM19: 375742 | AN19: 349627 | AO19: 92330 | AT19: info@kvestor.org | AW19: ООО «КВЕСТОР» зарегистрировано по адресу: 125252, Москва г, вн.тер.г. муниципальный округ Хорошевский, ул Авиаконструктора Микояна, д. 12, помещ. Б. Генеральным директором является Глаголев Роман Анатольевич.
A20: 3123458484 | B20: 540 | C20: Общество с ограниченной ответственностью «Коллекшн Консалт» | D20: 3123458484 | E20: 1193123020452 | F20: ООО «Коллекшн Консалт» | G20: 45642 | H20: 0 | I20: Нет | L20: г. Белгород, Народный б-р, д. 79, оф. 514, 308009 | M20: 10000 | R20: 41661 | S20: 209582 | T20: 225436 | U20: 273097 | W20: 25604 | X20: 73014 | Y20: 86775 | Z20: 327372 | AB20: 25604 | AC20: 96551 | AD20: 103277 | AE20: -93270 | AG20: 79789 | AH20: 149637 | AI20: 237909 | AJ20: 28531 | AL20: 1772 | AM20: 1066 | AN20: 1341 | AO20: 19433 | AT20: 0 | AW20: ООО «Коллекшн Консалт» зарегистрировано по адресу: г. Белгород, Народный б-р, д. 79, оф. 514, 308009
A21: 9704047900 | B21: 543 | C21: Акционерное общество «Технологии Бизнеса» | D21: 9704047900 | E21: 1217700057200 | F21: АО «Технологии Бизнеса» | G21: 45611 | H21: 0 | I21: Нет | L21: 119121, город Москва, вн.тер. г. Муниципальный Округ Хамовники, пер 2-Й Вражский, дом 1, корпус 1, помещение 1/1 | M21: 100 | R21: 0 | S21: 147758 | T21: 237367 | U21: 233367 | W21: 0 | X21: 89592 | Y21: 80711 | Z21: 96178 | AB21: 0 | AC21: 38966 | AD21: 26628 | AE21: 15952 | AG21: 0 | AH21: 23796 | AI21: 28911 | AJ21: 8099 | AL21: 0 | AM21: 17036 | AN21: 26891 | AO21: 20096 | AT21: info@ao-tb.ru | AW21: АО «Технологии Бизнеса» зарегистрировано по адресу: 119121, город Москва, вн.тер. г. Муниципальный Округ Хамовники, пер 2-Й Вражский, дом 1, корпус 1, помещение 1/1
A22: 2723115222 | B22: 0 | C22: Непубличное акционерное общество Профессиональная коллекторская организация «Первое клиентское бюро» | D22: 2723115222 | E22: 1092723000446 | F22: НАО ПКО «ПКБ» | G22: 39847 | H22: 16 | I22: Да | K22: Клековкин Николай Игоревич | L22: Москва г, км Киевское шоссе 22-й (п Московский), 6, 1 | M22: 194.3 | R22: 9519863 | S22: 7778417 | T22: 9298765 | U22: 12765053 | V22: 17486370 | W22: 4961407 | X22: 1886740 | Y22: 2913013 | Z22: 3028498 | AA22: 7354522 | AB22: 4961407 | AC22: 3327903 | AD22: 3667985 | AE22: 6746377 | AF22: 7017168 | AG22: 7094613 | AH22: 11961665 | AI22: 13692288 | AJ22: 23483962 | AK22: 21143934 | AL22: 410024 | AM22: 679296 | AN22: 874521 | AO22: 589736 | AP22: 522393 | AQ22: 12919181 | AR22: 1.84 | AS22: Низкий | AT22: pkbonline.ru | AU22: image060 | AV22: 2.98 | AW22: НАО ПКО «ПКБ» зарегистрировано по адресу: Москва г, км Киевское шоссе 22-й (п Московский), 6, 1. Генеральным директором является Клековкин Николай Игоревич. Рост доходов компании за 5 лет: 183,68%. Рост финансовых активов компании за 5 лет: 298,03%. Объем заемных средств компании на конец 2024 года: 12919181 тыс. руб. ФССП присвоил Низкий уровень риска для данного ПКО.
A23: 7713793524 | B23: 1 | C23: Общество с ограниченной ответственностью Профессиональная коллекторская организация «Феникс» | D23: 7713793524 | E23: 1147746920144 | F23: ООО ПКО «Феникс» | G23: 41863 | H23: 10 | I23: Нет | J23: Акционерное Общество, "ТБАНК", Международная Компания Публичное Акционерное Общество, "Т-ТЕХНОЛОГИИ" | K23: Феклисов Иван Владимирович | L23: 127287, Москва г, Хуторская 2-Я ул, дом 38А, строение 26 | M23: 33250 | R23: 7746710 | S23: 9815218 | T23: 10699598 | U23: 12291051 | V23: 12835953 | W23: 2407105 | X23: 3230796 | Y23: 3606574 | Z23: 2415999 | AA23: 1895600 | AB23: 2407105 | AC23: 5237831 | AD23: 5366147 | AE23: 7366870 | AF23: 8229971 | AG23: 9528726 | AH23: 8257159 | AI23: 11084910 | AJ23: 11562703 | AK23: 21154197 | AL23: 249470 | AM23: 63808 | AN23: 68805 | AO23: 61492 | AP23: 276242 | AQ23: 2378544 | AR23: 1.66 | AS23: Высокий | AT23: phoenix0ca.ru | AU23: image002 | AV23: 2.22 | AW23: ООО ПКО «Феникс» зарегистрировано по адресу: 127287, Москва г, Хуторская 2-Я ул, дом 38А, строение 26. Генеральным директором является Феклисов Иван Владимирович. Рост доходов компании за 5 лет: 165,7%. Рост финансовых активов компании за 5 лет: 222%. Объем заемных средств компании на конец 2024 года: 2378544 тыс. руб. ФССП присвоил Высокий уровень риска для данного ПКО.
A24: 7730233723 | B24: 4 | C24: Общество с ограниченной ответственностью профессиональная коллекторская организация «АйДи Коллект» | D24: 7730233723 | E24: 1177746355225 | F24: ООО ПКО «АйДи Коллект» | G24: 42832 | H24: 8 | I24: Да | J24: Васильев Александр Александрович, Общество С Ограниченной Ответственностью, "ОНЛАЙН МИКРОФИНАНС", Общество С Ограниченной Ответственностью, "ФИНТЕХ ГРУПП" | K24: Васильев Александр Александрович | L24: 121096, Москва г, ул. Василисы Кожиной, дом 1, офис Д13 | M24: 101265.82 | R24: 694023 | S24: 2342953 | T24: 4647772 | U24: 8331391 | V24: 12362455 | W24: 247799 | X24: 530090 | Y24: 1630652 | Z24: 2436827 | AA24: 4073731 | AB24: 247799 | AC24: 1119448 | AD24: 1329942 | AE24: 2975359 | AF24: 3863869 | AG24: 970210 | AH24: 4311265 | AI24: 7794949 | AJ24: 13782767 | AK24: 16179682 | AL24: 20331 | AM24: 31369 | AN24: 466385 | AO24: 289827 | AP24: 114237 | AQ24: 13646924 | AR24: 17.81 | AS24: Низкий | AT24: idcollect.ru | AU24: image043 | AV24: 16.68 | AW24: ООО ПКО «АйДи Коллект» зарегистрировано по адресу: 121096, Москва г, ул. Василисы Кожиной, дом 1, офис Д13. Генеральным директором является Васильев Александр Александрович. Рост доходов компании за 5 лет: 1781,3%. Рост финансовых активов компании за 5 лет: 1667,65%. Объем заемных средств компании на конец 2024 года: 13646924 тыс. руб. ФССП присвоил Низкий уровень риска для данного ПКО.
A25: 7714704125 | B25: 2 | C25: Общество с ограниченной ответственностью Профессиональная коллекторская организация «ЭОС» | D25: 7714704125 | E25: 1077758117117 | F25: ООО ПКО «ЭОС» | G25: 39282 | H25: 17 | I25: Да | J25: Завьялова Елена Михайловна, Компания С Ограниченной Ответственностью Эос Холдинг Гмбх, Компания С Ограниченной Ответственностью Эос Интернациональ Бетайлигунгс-фервальтунгсгезелльшафт Мбх | K25: Дмитраков Антон Александрович | L25: 117105, Москва г, вн.тер. г. муниципальный округ Нагорный, ш Варшавское, д. 26, этаж 2, ч. нежил. помещ. 8 | M25: 6450 | R25: 6360674 | S25: 9143168 | T25: 10606574 | U25: 11043025 | V25: 9784245 | W25: 1778110 | X25: 2163516 | Y25: 4978419 | Z25: 3027672 | AA25: 3020218 | AB25: 1778110 | AC25: 4582547 | AD25: 2928525 | AE25: 5120363 | AF25: 4762878 | AG25: 5308242 | AH25: 9409339 | AI25: 11291057 | AJ25: 12229815 | AK25: 11134188 | AL25: 76857 | AM25: 143059 | AN25: 80269 | AO25: 335476 | AP25: 169474 | AQ25: 5081951 | AR25: 1.54 | AS25: Низкий | AT25: oooeos.ru | AU25: image017 | AV25: 2.1 | AW25: ООО ПКО «ЭОС» зарегистрировано по адресу: 117105, Москва г, вн.тер. г. муниципальный округ Нагорный, ш Варшавское, д. 26, этаж 2, ч. нежил. помещ. 8. Генеральным директором является Дмитраков Антон Александрович. Рост доходов компании за 5 лет: 153,8%. Рост финансовых активов компании за 5 лет: 209,75%. Объем заемных средств компании на конец 2024 года: 5081951 тыс. руб. ФССП присвоил Низкий уровень риска для данного ПКО.
A26: 7706450420 | B26: 3 | C26: Общество с ограниченной ответственностью «Профессиональная коллекторская организация «Национальная Фабрика Ипотеки» | D26: 7706450420 | E26: 1177746942020 | F26: ООО «ПКО «Национальная Фабрика Ипотеки» | G26: 42984 | H26: 7 | I26: Нет | J26: "МОСКОВСКИЙ КРЕДИТНЫЙ БАНК", (публичное Акционерное Общество) | K26: Исеев Руслан Маратович | L26: 107140, Москва г, ул Красносельская Верхн., 11А, 1, 2/2/45 | M26: 315000 | R26: 8878559 | S26: 12637330 | T26: 12562020 | U26: 8536698 | V26: 8753853 | W26: 7464337 | X26: 11095638 | Y26: 10423574 | Z26: 6517008 | AA26: 6476527 | AB26: 7464337 | AC26: 230250 | AD26: 151795 | AE26: 137313 | AF26: -776176 | AG26: 6273480 | AH26: 8206211 | AI26: 10015293 | AJ26: 12684814 | AK26: 13806928 | AL26: 164797 | AM26: 187427 | AN26: 322258 | AO26: 439587 | AP26: 563914 | AQ26: 14942793 | AR26: 0.99 | AS26: Низкий | AT26: ipoteka24.ru | AU26: image142 | AV26: 2.2 | AW26: ООО «ПКО «Национальная Фабрика Ипотеки» зарегистрировано по адресу: 107140, Москва г, ул Красносельская Верхн., 11А, 1, 2/2/45. Генеральным директором является Исеев Руслан Маратович. Рост доходов компании за 5 лет: 98,6%. Рост финансовых активов компании за 5 лет: 220,08%. Объем заемных средств компании на конец 2024 года: 14942793 тыс. руб. ФССП присвоил Низкий уровень риска для данного ПКО.
A27: 5407973997 | B27: 8 | C27: Общество с ограниченной ответственностью Профессиональная коллекторская организация «Право онлайн» | D27: 5407973997 | E27: 1195476020343 | F27: ООО ПКО «Право онлайн» | G27: 43538 | H27: 6 | I27: Нет | J27: Волков Павел Александрович, Кравцова Наталья Николаевна, Евстифеева Юлия Евгеньевна, Кобяков Владислав Юрьевич, Елисеев Алексей Андреевич, Трахачёв Сергей Валерьевич | K27: Телятникова Елена Васильевна | L27: 630005, Новосибирская область, Новосибирск, Фрунзе, д. 88, этаж 2, офис 21 | M27: 62.035 | R27: 215252 | S27: 1025945 | T27: 2361430 | U27: 4627147 | V27: 7129755 | W27: 49016 | X27: 637310 | Y27: 1438435 | Z27: 2640709 | AA27: 4214695 | AB27: 49016 | AC27: 296990 | AD27: 684861 | AE27: 1273402 | AF27: 1879565 | AG27: 0 | AH27: 962059 | AI27: 2260288 | AJ27: 3547923 | AK27: 5850603 | AL27: 305122 | AM27: 116045 | AN27: 121243 | AO27: 273368 | AP27: 104605 | AQ27: 4008607 | AR27: 33.12 | AS27: Низкий | AT27: pvonline.ru | AU27: image057 | AV27: 6.08 | AW27: ООО ПКО «Право онлайн» зарегистрировано по адресу: 630005, Новосибирская область, Новосибирск, Фрунзе, д. 88, этаж 2, офис 21. Генеральным директором является Телятникова Елена Васильевна. Рост доходов компании за 5 лет: 3312,3%. Рост финансовых активов компании за 5 лет: 608,13%. Объем заемных средств компании на конец 2024 года: 4008607 тыс. руб. ФССП присвоил Низкий уровень риска для данного ПКО.
A28: 7841430420 | B28: 7 | C28: Общество с ограниченной ответственностью Профессиональная коллекторская организация «Филберт» | D28: 7841430420 | E28: 1107847250961 | F28: ООО ПКО «Филберт» | G28: 40394 | H28: 14 | I28: Да | K28: Иванов Андрей Борисович | L28: 198095, Санкт-Петербург г, Маршала Говорова ул, дом № 35, корпус 5, лит. Ж | M28: 10 | R28: 1770329 | S28: 4335154 | T28: 3848709 | U28: 4799034 | V28: 6148318 | W28: 348390 | X28: 1949395 | Y28: 621948 | Z28: 874797 | AA28: 1394961 | AB28: 348390 | AC28: 1315749 | AD28: 1802945 | AE28: 2218456 | AF28: 2568638 | AG28: 2620651 | AH28: 3839953 | AI28: 4999692 | AJ28: 7168661 | AK28: 9102226 | AL28: 50639 | AM28: 113684 | AN28: 55850 | AO28: 173771 | AP28: 69730 | AQ28: 2536194 | AR28: 3.47 | AS28: Значительный | AT28: filbert.su; Filbert.pro | AU28: image004 | AV28: 3.47 | AW28: ООО ПКО «Филберт» зарегистрировано по адресу: 198095, Санкт-Петербург г, Маршала Говорова ул, дом № 35, корпус 5, лит. Ж. Генеральным директором является Иванов Андрей Борисович. Рост доходов компании за 5 лет: 347,3%. Рост финансовых активов компании за 5 лет: 347,33%. Объем заемных средств компании на конец 2024 года: 2536194 тыс. руб. ФССП присвоил Значительный уровень риска для данного ПКО.
A29: 7707782563 | B29: 6 | C29: Общество с ограниченной ответственностью Профессиональная коллекторская организация «Региональная Служба Взыскания» | D29: 7707782563 | E29: 1127746618768 | F29: ООО ПКО «РСВ» | G29: 41131 | H29: 12 | I29: Да | J29: Общество С Ограниченной Ответственностью Профессиональная Коллекторская Организация, "СТОЛИЧНАЯ СЕРВИСНАЯ КОМПАНИЯ", Свеа Экономи Сайпрус Лимитед | K29: Медведева Ольга Владимировна | L29: 127055, Москва, Бутырский Вал, дом № 68/70, стр. 1, этаж 2, помещение I, комната №4 | M29: 10 | R29: 1034499 | S29: 3183461 | T29: 6096482 | U29: 5276121 | V29: 5864105 | W29: 450337 | X29: 674239 | Y29: 2086771 | Z29: 1622048 | AA29: 2473779 | AB29: 450337 | AC29: 1489776 | AD29: 2273861 | AE29: 2145981 | AF29: 3204091 | AG29: 1192462 | AH29: 4460750 | AI29: 4571756 | AJ29: 4530378 | AK29: 4794166 | AL29: 42936 | AM29: 204656 | AN29: 303021 | AO29: 569379 | AP29: 770038 | AQ29: 3181681 | AR29: 5.67 | AS29: Высокий | AT29: rsvcollection.ru | AU29: image020 | AV29: 4.02 | AW29: ООО ПКО «РСВ» зарегистрировано по адресу: 127055, Москва, Бутырский Вал, дом № 68/70, стр. 1, этаж 2, помещение I, комната №4. Генеральным директором является Медведева Ольга Владимировна. Рост доходов компании за 5 лет: 566,9%. Рост финансовых активов компании за 5 лет: 402,04%. Объем заемных средств компании на конец 2024 года: 3181681 тыс. руб. ФССП присвоил Высокий уровень риска для данного ПКО.
A30: 7730592401 | B30: 9 | C30: Акционерное общество Профессиональная коллекторская организация «Центр Долгового Управления» | D30: 7730592401 | E30: 5087746390353 | F30: АО ПКО «ЦДУ» | G30: 39763 | H30: 16 | I30: Нет | K30: Ямпольская Елена Александровна | L30: 117420, Москва г, ул Намёткина, 15, Эт 1 Пом I Ком 01-06 | M30: 3000 | R30: 662863 | S30: 1518917 | T30: 2355062 | U30: 3768972 | V30: 4706406 | W30: 187289 | X30: 590555 | Y30: 1392888 | Z30: 1955803 | AA30: 3014575 | AB30: 187289 | AC30: 774816 | AD30: 770441 | AE30: 1453064 | AF30: 1384779 | AG30: 260194 | AH30: 728282 | AI30: 1362348 | AJ30: 2486555 | AK30: 3311833 | AL30: 18583 | AM30: 66897 | AN30: 33544 | AO30: 65828 | AP30: 60950 | AQ30: 0 | AR30: 7.1 | AS30: Низкий | AT30: gkcdu.ru | AU30: image031 | AV30: 12.73 | AW30: АО ПКО «ЦДУ» зарегистрировано по адресу: 117420, Москва г, ул Намёткина, 15, Эт 1 Пом I Ком 01-06. Генеральным директором является Ямпольская Елена Александровна. Рост доходов компании за 5 лет: 710%. Рост финансовых активов компании за 5 лет: 1272,83%. ФССП присвоил Низкий уровень риска для данного ПКО.
A31: 3801084488 | B31: 10 | C31: Общество с ограниченной ответственностью Профессиональная коллекторская организация Траст» | D31: 3801084488 | E31: 1063801051203 | F31: ООО «ПКО Траст» | G31: 38945 | H31: 18 | I31: Да | J31: Долюк Андрей Николаевич, Самбудагва Ксения Павловна | K31: Долюк Андрей Николаевич | L31: 665801, Иркутская обл, г.о. Ангарское, г Ангарск, кв-л 252, стр. 19, д.офис 202 | M31: 20 | R31: 1314917 | S31: 2158767 | T31: 2677762 | U31: 3241552 | V31: 3666014 | W31: 200114 | X31: 397768 | Y31: 650661 | Z31: 1199595 | AA31: 1582938 | AB31: 200114 | AC31: 1060974 | AD31: 1244435 | AE31: 1194514 | AF31: 1296597 | AG31: 1544620 | AH31: 2163179 | AI31: 2962323 | AJ31: 4648416 | AK31: 5416881 | AL31: 58178 | AM31: 60606 | AN31: 80407 | AO31: 252788 | AP31: 177879 | AQ31: 463656 | AR31: 2.79 | AS31: Низкий | AT31: catrust.ru | AU31: image019 | AV31: 3.51 | AW31: ООО «ПКО Траст» зарегистрировано по адресу: 665801, Иркутская обл, г.о. Ангарское, г Ангарск, кв-л 252, стр. 19, д.офис 202. Генеральным директором является Долюк Андрей Николаевич. Рост доходов компании за 5 лет: 278,8%. Рост финансовых активов компании за 5 лет: 350,69%. Объем заемных средств компании на конец 2024 года: 463656 тыс. руб. ФССП присвоил Низкий уровень риска для данного ПКО.
A32: 7805646537 | B32: 14 | C32: Общество с ограниченной ответственностью профессиональная коллекторская организация «ДОЛГОВОЕ АГЕНТСТВО «ФЕМИДА» | D32: 7805646537 | E32: 1147847101577 | F32: ООО ПКО «ДА «ФЕМИДА» | G32: 41719 | H32: 11 | I32: Нет | J32: Общество С Ограниченной Ответственностью, "ДЗП-РАЗВИТИЕ" | K32: Карташова Ольга Владимировна | L32: 197374, Город Санкт-Петербург, ул. Мебельная, дом 12, корпус 1, литер А, помещение 55-Н, офис 420 | M32: 10 | R32: 133082 | S32: 154344 | T32: 474695 | U32: 2104307 | V32: 3049049 | W32: 175483 | X32: 57865 | Y32: 92399 | Z32: 840418 | AA32: 1267589 | AB32: 175483 | AC32: 3147 | AD32: 35182 | AE32: 520556 | AF32: 835826 | AG32: 206760 | AH32: 426247 | AI32: 910217 | AJ32: 1578595 | AK32: 1713500 | AL32: 37055 | AM32: 33373 | AN32: 7705 | AO32: 56903 | AP32: 85223 | AQ32: 137577 | AR32: 22.91 | AS32: Низкий | AT32: dafemida.ru | AU32: image175 | AV32: 8.29 | AW32: ООО ПКО «ДА «ФЕМИДА» зарегистрировано по адресу: 197374, Город Санкт-Петербург, ул. Мебельная, дом 12, корпус 1, литер А, помещение 55-Н, офис 420. Генеральным директором является Карташова Ольга Владимировна. Рост доходов компании за 5 лет: 2291,1%. Рост финансовых активов компании за 5 лет: 828,74%. Объем заемных средств компании на конец 2024 года: 137577 тыс. руб. ФССП присвоил Низкий уровень риска для данного ПКО.
A33: 7726626680 | B33: 13 | C33: Общество с ограниченной ответственностью «Профессиональная коллекторская организация «М.Б.А. Финансы» | D33: 7726626680 | E33: 1097746177693 | F33: ООО «ПКО «М.Б.А. Финансы» | G33: 39903 | H33: 16 | I33: Да | J33: Товарищество С Ограниченной Ответственностью, "КОЛЛЕКТОРСКОЕ АГЕНТСТВО ", М.б.а. Финансы" | K33: Вахата Федор | L33: 115280, Москва г, ул Мастеркова, 4, Эт 15 Пом I Ком 35 | M33: 200000 | R33: 1179086 | S33: 1453942 | T33: 2075137 | U33: 2301202 | V33: 2977193 | W33: -799983 | X33: -832060 | Y33: -1266296 | Z33: -1053945 | AA33: 1292887 | AB33: -799983 | AC33: 197045 | AD33: 263131 | AE33: 484044 | AF33: 749259 | AG33: 1151591 | AH33: 1391909 | AI33: 1557802 | AJ33: 1814461 | AK33: 2496513 | AL33: 175659 | AM33: 111498 | AN33: 150323 | AO33: 176690 | AP33: 212366 | AQ33: 365873 | AR33: 2.53 | AS33: Значительный | AT33: mbafin.ru | AU33: image044 | AV33: 2.17 | AW33: ООО «ПКО «М.Б.А. Финансы» зарегистрировано по адресу: 115280, Москва г, ул Мастеркова, 4, Эт 15 Пом I Ком 35. Генеральным директором является Вахата Федор. Рост доходов компании за 5 лет: 252,5%. Рост финансовых активов компании за 5 лет: 216,79%. Объем заемных средств компании на конец 2024 года: 365873 тыс. руб. ФССП присвоил Значительный уровень риска для данного ПКО.
A34: 7727844641 | B34: 16 | C34: Общество с ограниченной ответственностью Профессиональная коллекторская организация «ЦДУ Инвест» | D34: 7727844641 | E34: 5147746158632 | F34: ООО ПКО «ЦДУ Инвест» | G34: 41912 | H34: 10 | I34: Нет | J34: Креммель Александр Владимирович, Акционерное Общество Профессиональная Коллекторская Организация, "ЦЕНТР ДОЛГОВОГО УПРАВЛЕНИЯ" | K34: Смирнов Алексей Васильевич | L34: 117420, Москва г, ул Намёткина, 15, Эт/Пом/Ком 1/I/12 | M34: 3000 | R34: 111554 | S34: 374078 | T34: 754914 | U34: 1539322 | V34: 2413732 | W34: 40336 | X34: 120744 | Y34: 430376 | Z34: 632820 | AA34: 1427145 | AB34: 40336 | AC34: 200013 | AD34: 254498 | AE34: 705293 | AF34: 768428 | AG34: 41 | AH34: 277842 | AI34: 569806 | AJ34: 1193258 | AK34: 1762672 | AL34: 186115 | AM34: 67848 | AN34: 39920 | AO34: 26529 | AP34: 26529 | AQ34: 234000 | AR34: 21.64 | AS34: 0 | AT34: cdu0invest.ru | AU34: image308 | AV34: 42992 | AW34: ООО ПКО «ЦДУ Инвест» зарегистрировано по адресу: 117420, Москва г, ул Намёткина, 15, Эт/Пом/Ком 1/I/12. Генеральным директором является Смирнов Алексей Васильевич. Рост доходов компании за 5 лет: 2163,7%. Рост финансовых активов компании за 5 лет: 4299200%. Объем заемных средств компании на конец 2024 года: 234000 тыс. руб.
A35: 7841019595 | B35: 18 | C35: Общество с ограниченной ответственностью «Профессиональная коллекторская организация «Агентство Судебного Взыскания» | D35: 7841019595 | E35: 1157847071073 | F35: ООО «ПКО «АСВ» | G35: 42067 | H35: 10 | I35: Да | J35: Общество С Ограниченной Ответственностью, "АСВ.УПРАВЛЕНИЕ" | K35: Богомолов Максим Владимирович | L35: 194044, город Санкт-Петербург, вн.тер. г. Муниципальный Округ Сампсониевское, пр-кт Большой Сампсониевский, дом 28, корпус 2, литера Д, офис 642 | M35: 115.656 | R35: 483240 | S35: 784084 | T35: 1221840 | U35: 1469015 | V35: 2330001 | W35: 189104 | X35: 234597 | Y35: 514545 | Z35: 527752 | AA35: 833951 | AB35: 189104 | AC35: 39262 | AD35: 52476 | AE35: 65942 | AF35: 210834 | AG35: 178384 | AH35: 310830 | AI35: 535756 | AJ35: 1475570 | AK35: 1857986 | AL35: 71461 | AM35: 73708 | AN35: 61021 | AO35: 113400 | AP35: 231762 | AQ35: 2217172 | AR35: 4.82 | AS35: Низкий | AT35: legalcollection.ru | AU35: image204 | AV35: 10.42 | AW35: ООО «ПКО «АСВ» зарегистрировано по адресу: 194044, город Санкт-Петербург, вн.тер. г. Муниципальный Округ Сампсониевское, пр-кт Большой Сампсониевский, дом 28, корпус 2, литера Д, офис 642. Генеральным директором является Богомолов Максим Владимирович. Рост доходов компании за 5 лет: 482,2%. Рост финансовых активов компании за 5 лет: 1041,57%. Объем заемных средств компании на конец 2024 года: 2217172 тыс. руб. ФССП присвоил Низкий уровень риска для данного ПКО.
A36: 7736659589 | B36: 12 | C36: Общество с ограниченной ответственностью Профессиональная коллекторская организация «АктивБизнесКонсалт» | D36: 7736659589 | E36: 1137746390572 | F36: ООО ПКО «АБК» | G36: 41393 | H36: 11 | I36: Да | K36: Колосков Максим Викторович | L36: 117997, Москва г, ул Вавилова, 19 | M36: 16000 | R36: 1455949 | S36: 1701012 | T36: 2030719 | U36: 2352629 | V36: 2316584 | W36: 638929 | X36: 785795 | Y36: 943905 | Z36: 855231 | AA36: 969389 | AB36: 638929 | AC36: 439314 | AD36: 554003 | AE36: 803768 | AF36: 458487 | AG36: 497523 | AH36: 393123 | AI36: 821006 | AJ36: 2319520 | AK36: 3171955 | AL36: 102538 | AM36: 148122 | AN36: 135076 | AO36: 123795 | AP36: 164532 | AQ36: 2350687 | AR36: 1.59 | AS36: Низкий | AT36: activebc.ru | AU36: image041 | AV36: 6.38 | AW36: ООО ПКО «АБК» зарегистрировано по адресу: 117997, Москва г, ул Вавилова, 19. Генеральным директором является Колосков Максим Викторович. Рост доходов компании за 5 лет: 159,1%. Рост финансовых активов компании за 5 лет: 637,55%. Объем заемных средств компании на конец 2024 года: 2350687 тыс. руб. ФССП присвоил Низкий уровень риска для данного ПКО.
A37: 5407973637 | B37: 36 | C37: Общество с ограниченной ответственностью Профессиональная коллекторская организация «Защита Онлайн» | D37: 5407973637 | E37: 1195476015085 | F37: ООО ПКО «Защита Онлайн» | G37: 43521 | H37: 6 | I37: Да | J37: Волков Павел Александрович, Шин Егор Борисович, Евстифеева Юлия Евгеньевна, Елисеев Алексей Андреевич, Кобяков Владислав Юрьевич, Непомнящая Софья Алибековна, Сазонов Иван Викторович, Евтягина Ольга Владимировна, Зоткин Валерий Александрович, Загребельный Денис Александрович, Коуров Тимофей Анатольевич, Шарапов Константин Александрович, Трахачёв Сергей Валерьевич | K37: Загребельный Денис Александрович | L37: 630005, Новосибирская обл, г Новосибирск, ул Фрунзе, д. 88, этаж 3, офис 31 | M37: 150 | R37: 122897 | S37: 21903 | T37: 16511 | U37: 522072 | V37: 1885826 | W37: 3853 | X37: 5411 | Y37: 14851 | Z37: 294040 | AA37: 1053672 | AB37: 3853 | AC37: 14072 | AD37: 29 | AE37: 117762 | AF37: 500453 | AG37: 0 | AH37: 0 | AI37: 0 | AJ37: 1305806 | AK37: 2387910 | AL37: 126639 | AM37: 37595 | AN37: 107807 | AO37: 23530 | AP37: 50562 | AQ37: 1677758 | AR37: 15.35 | AS37: Низкий | AT37: https://zonline.ru/ | AU37: image234 | AV37: 1.83 | AW37: ООО ПКО «Защита Онлайн» зарегистрировано по адресу: 630005, Новосибирская обл, г Новосибирск, ул Фрунзе, д. 88, этаж 3, офис 31. Генеральным директором является Загребельный Денис Александрович. Рост доходов компании за 5 лет: 1534,5%. Рост финансовых активов компании за 5 лет: 182,87%. Объем заемных средств компании на конец 2024 года: 1677758 тыс. руб. ФССП присвоил Низкий уровень риска для данного ПКО.
A38: 6315626402 | B38: 11 | C38: Общество с ограниченной ответственностью Профессиональная коллекторская организация «Сентинел Кредит Менеджмент» | D38: 6315626402 | E38: 1096315004720 | F38: ООО ПКО «СКМ» | G38: 40024 | H38: 15 | I38: Да | K38: Дуда Игорь Викторович | L38: 121151, Москва, Тараса Шевченко, 23А | M38: 216547 | R38: 972350 | S38: 1937261 | T38: 1781010 | U38: 2696180 | V38: 1611463 | W38: 697366 | X38: 707941 | Y38: 661037 | Z38: 852713 | AA38: 411601 | AB38: 29174 | AC38: 813058 | AD38: 547425 | AE38: 1130465 | AF38: 569404 | AG38: 623346 | AH38: 997343 | AI38: 1002540 | AJ38: 830364 | AK38: 1175885 | AL38: 93343 | AM38: 165191 | AN38: 196659 | AO38: 176870 | AP38: 176870 | AQ38: 837000 | AR38: 1.66 | AS38: Значительный | AT38: sentinelcredit.ru | AU38: image024 | AV38: 1.89 | AW38: ООО ПКО «СКМ» зарегистрировано по адресу: 121151, Москва, Тараса Шевченко, 23А. Генеральным директором является Дуда Игорь Викторович. Рост доходов компании за 5 лет: 165,7%. Рост финансовых активов компании за 5 лет: 188,64%. Объем заемных средств компании на конец 2024 года: 837000 тыс. руб. ФССП присвоил Значительный уровень риска для данного ПКО.
A39: 1657199916 | B39: 19 | C39: Общество с ограниченной ответственностью Профессиональная коллекторская организация «Фабула» | D39: 1657199916 | E39: 1151690071741 | F39: ООО ПКО «Фабула» | G39: 42256 | H39: 9 | I39: Нет | J39: Общество С Ограниченной Ответственностью, "ЛЕГАЛАЙТ" | K39: Диянов Радик Рашидович | L39: 420044, Татарстан Респ, Казань г, Ямашева пр-кт, дом № 36Д, офис 15 | M39: 15000 | R39: 432196 | S39: 688012 | T39: 902262 | U39: 1373573 | V39: 1584330 | W39: 96637 | X39: 165381 | Y39: 295097 | Z39: 562133 | AA39: 676507 | AB39: 96637 | AC39: 316576 | AD39: 378643 | AE39: 498600 | AF39: 577188 | AG39: 184152 | AH39: 497285 | AI39: 678648 | AJ39: 1031369 | AK39: 1319603 | AL39: 137587 | AM39: 119788 | AN39: 179893 | AO39: 207466 | AP39: 345144 | AQ39: 0 | AR39: 3.67 | AS39: Низкий | AT39: kafabula.ru | AU39: image036 | AV39: 7.17 | AW39: ООО ПКО «Фабула» зарегистрировано по адресу: 420044, Татарстан Респ, Казань г, Ямашева пр-кт, дом № 36Д, офис 15. Генеральным директором является Диянов Радик Рашидович. Рост доходов компании за 5 лет: 366,6%. Рост финансовых активов компании за 5 лет: 716,58%. ФССП присвоил Низкий уровень риска для данного ПКО.
A40: 6672302726 | B40: 5 | C40: Общество с ограниченной ответственностью «Профессиональная коллекторская организация «ФинТраст» | D40: 6672302726 | E40: 1096672015648 | F40: ООО «ПКО «ФинТраст» | G40: 40070 | H40: 15 | I40: Нет | J40: Шалимов Константин Викторович | K40: Шалимов Константин Викторович | L40: 620026, Свердловская обл, г Екатеринбург, ул Куйбышева, 95, 405 | M40: 10 | R40: 3566972 | S40: 4673205 | T40: 3611889 | U40: 6243476 | V40: 1394242 | W40: 3390488 | X40: 4521453 | Y40: 2810324 | Z40: 5403598 | AA40: 493549 | AB40: 3390488 | AC40: 5951 | AD40: 12656 | AE40: 17407 | AF40: -86162 | AG40: 6827666 | AH40: 10091197 | AI40: 10480485 | AJ40: 8517263 | AK40: 8583581 | AL40: 886 | AM40: 585819 | AN40: 4047773 | AO40: 1415320 | AP40: 1415320 | AQ40: 10012498 | AR40: 0.39 | AS40: 0 | AT40: cafintrust.ru | AU40: image350 | AV40: 1.26 | AW40: ООО «ПКО «ФинТраст» зарегистрировано по адресу: 620026, Свердловская обл, г Екатеринбург, ул Куйбышева, 95, 405. Генеральным директором является Шалимов Константин Викторович. Рост доходов компании за 5 лет: 39,1%. Рост финансовых активов компании за 5 лет: 125,72%. Объем заемных средств компании на конец 2024 года: 10012498 тыс. руб.
...

Sheet old_Расчет
A1: id | B1: name | C1: inn | D1: ogrn | E1: name_light | F1: date_register | G1: working_years | H1: napka | I1: founder | J1: director | K1: adress | L1: capital | M1: agent | N1: raiting_get_a | O1: cess | P1: raiting_get_c | Q1: income2020 | R1: income2021 | S1: income2022 | T1: income2023 | U1: income2024 | V1: cost2020 | W1: cost2021 | X1: cost2022 | Y1: cost2023 | Z1: cost2024 | AA1: profit2020 | AB1: profit2021 | AC1: profit2022 | AD1: profit2023 | AE1: profit2024 | AF1: invest2020 | AG1: invest2021 | AH1: invest2022 | AI1: invest2023 | AJ1: invest2024 | AK1: receivable2020 | AL1: receivable2021 | AM1: receivable2022 | AN1: receivable2023 | AO1: receivable2024 | AP1: loan | AQ1: grow_income_2019_2023 | AR1: risk_fssp | AS1: site | AT1: logo | AU1: temp_grow_2019_2023 | AV1: description | AY1: 45769
A2: 0 | B2: Непубличное акционерное общество Профессиональная коллекторская организация «Первое клиентское бюро» | C2: 2723115222 | D2: 1092723000446 | E2: НАО ПКО «ПКБ» | F2: 39847 | G2: =ROUNDDOWN(($AY$1-F2)/365,0) -> 16 | H2: Да | I2: =IF(VLOOKUP(C2,гендир!$A$3:$C$3000,3,0)=0,"",VLOOKUP(C2,гендир!$A$3:$C$3000,3,0)) | J2: =IF(VLOOKUP(C2,гендир!$A$3:$C$3000,2,0)=0,"",VLOOKUP(C2,гендир!$A$3:$C$3000,2,0)) -> Клековкин Николай Игоревич | K2: Москва г, км Киевское шоссе 22-й (п Московский), 6, 1 | L2: 194.3 | P2: 1 | Q2: 9519863 | R2: 7778417 | S2: 9298765 | T2: 12765053 | U2: 17486370 | V2: 4961407 | W2: 1886740 | X2: 2913013 | Y2: 3028498 | Z2: 7354522 | AA2: 4961407 | AB2: 3327903 | AC2: 3667985 | AD2: 6746377 | AE2: 7017168 | AF2: 7094613 | AG2: 11961665 | AH2: 13692288 | AI2: 23483962 | AJ2: 21143934 | AK2: 410024 | AL2: 679296 | AM2: 874521 | AN2: 589736 | AO2: 522393 | AP2: 12919181 | AQ2: 1.83683 | AR2: Низкий | AS2: pkbonline.ru | AT2: =IF(VLOOKUP(C2,old!$D$3:$AU$549,44,0)=0,"",VLOOKUP(C2,old!$D$3:$AU$549,44,0)) -> image060 | AU2: 2.9802801 | AV2: =E2&" зарегистрировано по адресу: "&K2&IF(J2=0,"",IF(J2="","",". Генеральным директором является "&J2&IF(AQ2=0,".",IF(AQ2="",".",". Рост доходов компании за 5 лет: "&ROUND(AQ2*100,2)&"%."))&IF(AU2=0,"",IF(AU2="",""," Рост финансовых активов компании за 5 лет: "&IFERROR(ROUND(AU2*100,2),"")&"%."))&IF(AP2=0,"",IF(AP2="",""," Объем заемных средств компании на конец 2024 года: "&AP2&" тыс. руб."))&IF(AR2=0,"",IF(AR2="",""," ФССП присвоил "&AR2&" уровень риска для данного ПКО.")))) -> НАО ПКО «ПКБ» зарегистрировано по адресу: Москва г, км Киевское шоссе 22-й (п Московский), 6, 1. Генеральным директором является Клековкин Николай Игоревич. Рост доходов компании за 5 лет: 183,68%. Рост финансовых активов компании за 5 лет: 298,03%. Объем заемных средств компании на конец 2024 года: 12919181 тыс. руб. ФССП присвоил Низкий уровень риска для данного ПКО.
A3: 1 | B3: Общество с ограниченной ответственностью Профессиональная коллекторская организация «Феникс» | C3: 7713793524 | D3: 1147746920144 | E3: ООО ПКО «Феникс» | F3: 41863 | G3: =ROUNDDOWN(($AY$1-F3)/365,0) -> 10 | H3: Нет | I3: =IF(VLOOKUP(C3,гендир!$A$3:$C$3000,3,0)=0,"",VLOOKUP(C3,гендир!$A$3:$C$3000,3,0)) -> Акционерное Общество, "ТБАНК", Международная Компания Публичное Акционерное Общество, "Т-ТЕХНОЛОГИИ" | J3: =IF(VLOOKUP(C3,гендир!$A$3:$C$3000,2,0)=0,"",VLOOKUP(C3,гендир!$A$3:$C$3000,2,0)) -> Феклисов Иван Владимирович | K3: 127287, Москва г, Хуторская 2-Я ул, дом 38А, строение 26 | L3: 33250 | P3: 2 | Q3: 7746710 | R3: 9815218 | S3: 10699598 | T3: 12291051 | U3: 12835953 | V3: 2407105 | W3: 3230796 | X3: 3606574 | Y3: 2415999 | Z3: 1895600 | AA3: 2407105 | AB3: 5237831 | AC3: 5366147 | AD3: 7366870 | AE3: 8229971 | AF3: 9528726 | AG3: 8257159 | AH3: 11084910 | AI3: 11562703 | AJ3: 21154197 | AK3: 249470 | AL3: 63808 | AM3: 68805 | AN3: 61492 | AO3: 276242 | AP3: 2378544 | AQ3: =IFERROR(ROUND(IFERROR(U3/Q3,IFERROR(U3/R3,IFERROR(U3/S3,IFERROR(U3/T3,"")))),3),"") -> 1.657 | AR3: Высокий | AS3: phoenix0ca.ru | AT3: =IF(VLOOKUP(C3,old!$D$3:$AU$549,44,0)=0,"",VLOOKUP(C3,old!$D$3:$AU$549,44,0)) -> image002 | AU3: 2.2200446 | AV3: =E3&" зарегистрировано по адресу: "&K3&IF(J3=0,"",IF(J3="","",". Генеральным директором является "&J3&IF(AQ3=0,".",IF(AQ3="",".",". Рост доходов компании за 5 лет: "&ROUND(AQ3*100,2)&"%."))&IF(AU3=0,"",IF(AU3="",""," Рост финансовых активов компании за 5 лет: "&IFERROR(ROUND(AU3*100,2),"")&"%."))&IF(AP3=0,"",IF(AP3="",""," Объем заемных средств компании на конец 2024 года: "&AP3&" тыс. руб."))&IF(AR3=0,"",IF(AR3="",""," ФССП присвоил "&AR3&" уровень риска для данного ПКО.")))) -> ООО ПКО «Феникс» зарегистрировано по адресу: 127287, Москва г, Хуторская 2-Я ул, дом 38А, строение 26. Генеральным директором является Феклисов Иван Владимирович. Рост доходов компании за 5 лет: 165,7%. Рост финансовых активов компании за 5 лет: 222%. Объем заемных средств компании на конец 2024 года: 2378544 тыс. руб. ФССП присвоил Высокий уровень риска для данного ПКО.
A4: 4 | B4: Общество с ограниченной ответственностью профессиональная коллекторская организация «АйДи Коллект» | C4: 7730233723 | D4: 1177746355225 | E4: ООО ПКО «АйДи Коллект» | F4: 42832 | G4: =ROUNDDOWN(($AY$1-F4)/365,0) -> 8 | H4: Да | I4: =IF(VLOOKUP(C4,гендир!$A$3:$C$3000,3,0)=0,"",VLOOKUP(C4,гендир!$A$3:$C$3000,3,0)) -> Васильев Александр Александрович, Общество С Ограниченной Ответственностью, "ОНЛАЙН МИКРОФИНАНС", Общество С Ограниченной Ответственностью, "ФИНТЕХ ГРУПП" | J4: =IF(VLOOKUP(C4,гендир!$A$3:$C$3000,2,0)=0,"",VLOOKUP(C4,гендир!$A$3:$C$3000,2,0)) -> Васильев Александр Александрович | K4: 121096, Москва г, ул. Василисы Кожиной, дом 1, офис Д13 | L4: 101265.82 | P4: 3 | Q4: 694023 | R4: 2342953 | S4: 4647772 | T4: 8331391 | U4: 12362455 | V4: 247799 | W4: 530090 | X4: 1630652 | Y4: 2436827 | Z4: 4073731 | AA4: 247799 | AB4: 1119448 | AC4: 1329942 | AD4: 2975359 | AE4: 3863869 | AF4: 970210 | AG4: 4311265 | AH4: 7794949 | AI4: 13782767 | AJ4: 16179682 | AK4: 20331 | AL4: 31369 | AM4: 466385 | AN4: 289827 | AO4: 114237 | AP4: 13646924 | AQ4: =IFERROR(ROUND(IFERROR(U4/Q4,IFERROR(U4/R4,IFERROR(U4/S4,IFERROR(U4/T4,"")))),3),"") -> 17.813 | AR4: Низкий | AS4: idcollect.ru | AT4: =IF(VLOOKUP(C4,old!$D$3:$AU$549,44,0)=0,"",VLOOKUP(C4,old!$D$3:$AU$549,44,0)) -> image043 | AU4: 16.676474 | AV4: =E4&" зарегистрировано по адресу: "&K4&IF(J4=0,"",IF(J4="","",". Генеральным директором является "&J4&IF(AQ4=0,".",IF(AQ4="",".",". Рост доходов компании за 5 лет: "&ROUND(AQ4*100,2)&"%."))&IF(AU4=0,"",IF(AU4="",""," Рост финансовых активов компании за 5 лет: "&IFERROR(ROUND(AU4*100,2),"")&"%."))&IF(AP4=0,"",IF(AP4="",""," Объем заемных средств компании на конец 2024 года: "&AP4&" тыс. руб."))&IF(AR4=0,"",IF(AR4="",""," ФССП присвоил "&AR4&" уровень риска для данного ПКО.")))) -> ООО ПКО «АйДи Коллект» зарегистрировано по адресу: 121096, Москва г, ул. Василисы Кожиной, дом 1, офис Д13. Генеральным директором является Васильев Александр Александрович. Рост доходов компании за 5 лет: 1781,3%. Рост финансовых активов компании за 5 лет: 1667,65%. Объем заемных средств компании на конец 2024 года: 13646924 тыс. руб. ФССП присвоил Низкий уровень риска для данного ПКО.
A5: 2 | B5: Общество с ограниченной ответственностью Профессиональная коллекторская организация «ЭОС» | C5: 7714704125 | D5: 1077758117117 | E5: ООО ПКО «ЭОС» | F5: 39282 | G5: =ROUNDDOWN(($AY$1-F5)/365,0) -> 17 | H5: Да | I5: =IF(VLOOKUP(C5,гендир!$A$3:$C$3000,3,0)=0,"",VLOOKUP(C5,гендир!$A$3:$C$3000,3,0)) -> Завьялова Елена Михайловна, Компания С Ограниченной Ответственностью Эос Холдинг Гмбх, Компания С Ограниченной Ответственностью Эос Интернациональ Бетайлигунгс-фервальтунгсгезелльшафт Мбх | J5: =IF(VLOOKUP(C5,гендир!$A$3:$C$3000,2,0)=0,"",VLOOKUP(C5,гендир!$A$3:$C$3000,2,0)) -> Дмитраков Антон Александрович | K5: 117105, Москва г, вн.тер. г. муниципальный округ Нагорный, ш Варшавское, д. 26, этаж 2, ч. нежил. помещ. 8 | L5: 6450 | P5: 4 | Q5: 6360674 | R5: 9143168 | S5: 10606574 | T5: 11043025 | U5: 9784245 | V5: 1778110 | W5: 2163516 | X5: 4978419 | Y5: 3027672 | Z5: 3020218 | AA5: 1778110 | AB5: 4582547 | AC5: 2928525 | AD5: 5120363 | AE5: 4762878 | AF5: 5308242 | AG5: 9409339 | AH5: 11291057 | AI5: 12229815 | AJ5: 11134188 | AK5: 76857 | AL5: 143059 | AM5: 80269 | AN5: 335476 | AO5: 169474 | AP5: 5081951 | AQ5: =IFERROR(ROUND(IFERROR(U5/Q5,IFERROR(U5/R5,IFERROR(U5/S5,IFERROR(U5/T5,"")))),3),"") -> 1.538 | AR5: Низкий | AS5: oooeos.ru | AT5: =IF(VLOOKUP(C5,old!$D$3:$AU$549,44,0)=0,"",VLOOKUP(C5,old!$D$3:$AU$549,44,0)) -> image017 | AU5: 2.0975283 | AV5: =E5&" зарегистрировано по адресу: "&K5&IF(J5=0,"",IF(J5="","",". Генеральным директором является "&J5&IF(AQ5=0,".",IF(AQ5="",".",". Рост доходов компании за 5 лет: "&ROUND(AQ5*100,2)&"%."))&IF(AU5=0,"",IF(AU5="",""," Рост финансовых активов компании за 5 лет: "&IFERROR(ROUND(AU5*100,2),"")&"%."))&IF(AP5=0,"",IF(AP5="",""," Объем заемных средств компании на конец 2024 года: "&AP5&" тыс. руб."))&IF(AR5=0,"",IF(AR5="",""," ФССП присвоил "&AR5&" уровень риска для данного ПКО.")))) -> ООО ПКО «ЭОС» зарегистрировано по адресу: 117105, Москва г, вн.тер. г. муниципальный округ Нагорный, ш Варшавское, д. 26, этаж 2, ч. нежил. помещ. 8. Генеральным директором является Дмитраков Антон Александрович. Рост доходов компании за 5 лет: 153,8%. Рост финансовых активов компании за 5 лет: 209,75%. Объем заемных средств компании на конец 2024 года: 5081951 тыс. руб. ФССП присвоил Низкий уровень риска для данного ПКО.
A6: 3 | B6: Общество с ограниченной ответственностью «Профессиональная коллекторская организация «Национальная Фабрика Ипотеки» | C6: 7706450420 | D6: 1177746942020 | E6: ООО «ПКО «Национальная Фабрика Ипотеки» | F6: 42984 | G6: =ROUNDDOWN(($AY$1-F6)/365,0) -> 7 | H6: Нет | I6: =IF(VLOOKUP(C6,гендир!$A$3:$C$3000,3,0)=0,"",VLOOKUP(C6,гендир!$A$3:$C$3000,3,0)) -> "МОСКОВСКИЙ КРЕДИТНЫЙ БАНК", (публичное Акционерное Общество) | J6: =IF(VLOOKUP(C6,гендир!$A$3:$C$3000,2,0)=0,"",VLOOKUP(C6,гендир!$A$3:$C$3000,2,0)) -> Исеев Руслан Маратович | K6: 107140, Москва г, ул Красносельская Верхн., 11А, 1, 2/2/45 | L6: 315000 | P6: 5 | Q6: 8878559 | R6: 12637330 | S6: 12562020 | T6: 8536698 | U6: 8753853 | V6: 7464337 | W6: 11095638 | X6: 10423574 | Y6: 6517008 | Z6: 6476527 | AA6: 7464337 | AB6: 230250 | AC6: 151795 | AD6: 137313 | AE6: -776176 | AF6: 6273480 | AG6: 8206211 | AH6: 10015293 | AI6: 12684814 | AJ6: 13806928 | AK6: 164797 | AL6: 187427 | AM6: 322258 | AN6: 439587 | AO6: 563914 | AP6: 14942793 | AQ6: =IFERROR(ROUND(IFERROR(U6/Q6,IFERROR(U6/R6,IFERROR(U6/S6,IFERROR(U6/T6,"")))),3),"") -> 0.986 | AR6: Низкий | AS6: ipoteka24.ru | AT6: =IF(VLOOKUP(C6,old!$D$3:$AU$549,44,0)=0,"",VLOOKUP(C6,old!$D$3:$AU$549,44,0)) -> image142 | AU6: 2.2008404 | AV6: =E6&" зарегистрировано по адресу: "&K6&IF(J6=0,"",IF(J6="","",". Генеральным директором является "&J6&IF(AQ6=0,".",IF(AQ6="",".",". Рост доходов компании за 5 лет: "&ROUND(AQ6*100,2)&"%."))&IF(AU6=0,"",IF(AU6="",""," Рост финансовых активов компании за 5 лет: "&IFERROR(ROUND(AU6*100,2),"")&"%."))&IF(AP6=0,"",IF(AP6="",""," Объем заемных средств компании на конец 2024 года: "&AP6&" тыс. руб."))&IF(AR6=0,"",IF(AR6="",""," ФССП присвоил "&AR6&" уровень риска для данного ПКО.")))) -> ООО «ПКО «Национальная Фабрика Ипотеки» зарегистрировано по адресу: 107140, Москва г, ул Красносельская Верхн., 11А, 1, 2/2/45. Генеральным директором является Исеев Руслан Маратович. Рост доходов компании за 5 лет: 98,6%. Рост финансовых активов компании за 5 лет: 220,08%. Объем заемных средств компании на конец 2024 года: 14942793 тыс. руб. ФССП присвоил Низкий уровень риска для данного ПКО.
A7: 8 | B7: Общество с ограниченной ответственностью Профессиональная коллекторская организация «Право онлайн» | C7: 5407973997 | D7: 1195476020343 | E7: ООО ПКО «Право онлайн» | F7: 43538 | G7: =ROUNDDOWN(($AY$1-F7)/365,0) -> 6 | H7: Нет | I7: =IF(VLOOKUP(C7,гендир!$A$3:$C$3000,3,0)=0,"",VLOOKUP(C7,гендир!$A$3:$C$3000,3,0)) -> Волков Павел Александрович, Кравцова Наталья Николаевна, Евстифеева Юлия Евгеньевна, Кобяков Владислав Юрьевич, Елисеев Алексей Андреевич, Трахачёв Сергей Валерьевич | J7: =IF(VLOOKUP(C7,гендир!$A$3:$C$3000,2,0)=0,"",VLOOKUP(C7,гендир!$A$3:$C$3000,2,0)) -> Телятникова Елена Васильевна | K7: 630005, Новосибирская область, Новосибирск, Фрунзе, д. 88, этаж 2, офис 21 | L7: 62.035 | P7: 6 | Q7: 215252 | R7: 1025945 | S7: 2361430 | T7: 4627147 | U7: 7129755 | V7: 49016 | W7: 637310 | X7: 1438435 | Y7: 2640709 | Z7: 4214695 | AA7: 49016 | AB7: 296990 | AC7: 684861 | AD7: 1273402 | AE7: 1879565 | AF7: 0 | AG7: 962059 | AH7: 2260288 | AI7: 3547923 | AJ7: 5850603 | AK7: 305122 | AL7: 116045 | AM7: 121243 | AN7: 273368 | AO7: 104605 | AP7: 4008607 | AQ7: =IFERROR(ROUND(IFERROR(U7/Q7,IFERROR(U7/R7,IFERROR(U7/S7,IFERROR(U7/T7,"")))),3),"") -> 33.123 | AR7: Низкий | AS7: pvonline.ru | AT7: =IF(VLOOKUP(C7,old!$D$3:$AU$549,44,0)=0,"",VLOOKUP(C7,old!$D$3:$AU$549,44,0)) -> image057 | AU7: 6.0813349 | AV7: =E7&" зарегистрировано по адресу: "&K7&IF(J7=0,"",IF(J7="","",". Генеральным директором является "&J7&IF(AQ7=0,".",IF(AQ7="",".",". Рост доходов компании за 5 лет: "&ROUND(AQ7*100,2)&"%."))&IF(AU7=0,"",IF(AU7="",""," Рост финансовых активов компании за 5 лет: "&IFERROR(ROUND(AU7*100,2),"")&"%."))&IF(AP7=0,"",IF(AP7="",""," Объем заемных средств компании на конец 2024 года: "&AP7&" тыс. руб."))&IF(AR7=0,"",IF(AR7="",""," ФССП присвоил "&AR7&" уровень риска для данного ПКО.")))) -> ООО ПКО «Право онлайн» зарегистрировано по адресу: 630005, Новосибирская область, Новосибирск, Фрунзе, д. 88, этаж 2, офис 21. Генеральным директором является Телятникова Елена Васильевна. Рост доходов компании за 5 лет: 3312,3%. Рост финансовых активов компании за 5 лет: 608,13%. Объем заемных средств компании на конец 2024 года: 4008607 тыс. руб. ФССП присвоил Низкий уровень риска для данного ПКО.
A8: 7 | B8: Общество с ограниченной ответственностью Профессиональная коллекторская организация «Филберт» | C8: 7841430420 | D8: 1107847250961 | E8: ООО ПКО «Филберт» | F8: 40394 | G8: =ROUNDDOWN(($AY$1-F8)/365,0) -> 14 | H8: Да | I8: =IF(VLOOKUP(C8,гендир!$A$3:$C$3000,3,0)=0,"",VLOOKUP(C8,гендир!$A$3:$C$3000,3,0)) | J8: =IF(VLOOKUP(C8,гендир!$A$3:$C$3000,2,0)=0,"",VLOOKUP(C8,гендир!$A$3:$C$3000,2,0)) -> Иванов Андрей Борисович | K8: 198095, Санкт-Петербург г, Маршала Говорова ул, дом № 35, корпус 5, лит. Ж | L8: 10 | P8: 7 | Q8: 1770329 | R8: 4335154 | S8: 3848709 | T8: 4799034 | U8: 6148318 | V8: 348390 | W8: 1949395 | X8: 621948 | Y8: 874797 | Z8: 1394961 | AA8: 348390 | AB8: 1315749 | AC8: 1802945 | AD8: 2218456 | AE8: 2568638 | AF8: 2620651 | AG8: 3839953 | AH8: 4999692 | AI8: 7168661 | AJ8: 9102226 | AK8: 50639 | AL8: 113684 | AM8: 55850 | AN8: 173771 | AO8: 69730 | AP8: 2536194 | AQ8: =IFERROR(ROUND(IFERROR(U8/Q8,IFERROR(U8/R8,IFERROR(U8/S8,IFERROR(U8/T8,"")))),3),"") -> 3.473 | AR8: Значительный | AS8: filbert.su; Filbert.pro | AT8: =IF(VLOOKUP(C8,old!$D$3:$AU$549,44,0)=0,"",VLOOKUP(C8,old!$D$3:$AU$549,44,0)) -> image004 | AU8: 3.473269 | AV8: =E8&" зарегистрировано по адресу: "&K8&IF(J8=0,"",IF(J8="","",". Генеральным директором является "&J8&IF(AQ8=0,".",IF(AQ8="",".",". Рост доходов компании за 5 лет: "&ROUND(AQ8*100,2)&"%."))&IF(AU8=0,"",IF(AU8="",""," Рост финансовых активов компании за 5 лет: "&IFERROR(ROUND(AU8*100,2),"")&"%."))&IF(AP8=0,"",IF(AP8="",""," Объем заемных средств компании на конец 2024 года: "&AP8&" тыс. руб."))&IF(AR8=0,"",IF(AR8="",""," ФССП присвоил "&AR8&" уровень риска для данного ПКО.")))) -> ООО ПКО «Филберт» зарегистрировано по адресу: 198095, Санкт-Петербург г, Маршала Говорова ул, дом № 35, корпус 5, лит. Ж. Генеральным директором является Иванов Андрей Борисович. Рост доходов компании за 5 лет: 347,3%. Рост финансовых активов компании за 5 лет: 347,33%. Объем заемных средств компании на конец 2024 года: 2536194 тыс. руб. ФССП присвоил Значительный уровень риска для данного ПКО.
A9: 6 | B9: Общество с ограниченной ответственностью Профессиональная коллекторская организация «Региональная Служба Взыскания» | C9: 7707782563 | D9: 1127746618768 | E9: ООО ПКО «РСВ» | F9: 41131 | G9: =ROUNDDOWN(($AY$1-F9)/365,0) -> 12 | H9: Да | I9: =IF(VLOOKUP(C9,гендир!$A$3:$C$3000,3,0)=0,"",VLOOKUP(C9,гендир!$A$3:$C$3000,3,0)) -> Общество С Ограниченной Ответственностью Профессиональная Коллекторская Организация, "СТОЛИЧНАЯ СЕРВИСНАЯ КОМПАНИЯ", Свеа Экономи Сайпрус Лимитед | J9: =IF(VLOOKUP(C9,гендир!$A$3:$C$3000,2,0)=0,"",VLOOKUP(C9,гендир!$A$3:$C$3000,2,0)) -> Медведева Ольга Владимировна | K9: 127055, Москва, Бутырский Вал, дом № 68/70, стр. 1, этаж 2, помещение I, комната №4 | L9: 10 | P9: 8 | Q9: 1034499 | R9: 3183461 | S9: 6096482 | T9: 5276121 | U9: 5864105 | V9: 450337 | W9: 674239 | X9: 2086771 | Y9: 1622048 | Z9: 2473779 | AA9: 450337 | AB9: 1489776 | AC9: 2273861 | AD9: 2145981 | AE9: 3204091 | AF9: 1192462 | AG9: 4460750 | AH9: 4571756 | AI9: 4530378 | AJ9: 4794166 | AK9: 42936 | AL9: 204656 | AM9: 303021 | AN9: 569379 | AO9: 770038 | AP9: 3181681 | AQ9: =IFERROR(ROUND(IFERROR(U9/Q9,IFERROR(U9/R9,IFERROR(U9/S9,IFERROR(U9/T9,"")))),3),"") -> 5.669 | AR9: Высокий | AS9: rsvcollection.ru | AT9: =IF(VLOOKUP(C9,old!$D$3:$AU$549,44,0)=0,"",VLOOKUP(C9,old!$D$3:$AU$549,44,0)) -> image020 | AU9: 4.0203931 | AV9: =E9&" зарегистрировано по адресу: "&K9&IF(J9=0,"",IF(J9="","",". Генеральным директором является "&J9&IF(AQ9=0,".",IF(AQ9="",".",". Рост доходов компании за 5 лет: "&ROUND(AQ9*100,2)&"%."))&IF(AU9=0,"",IF(AU9="",""," Рост финансовых активов компании за 5 лет: "&IFERROR(ROUND(AU9*100,2),"")&"%."))&IF(AP9=0,"",IF(AP9="",""," Объем заемных средств компании на конец 2024 года: "&AP9&" тыс. руб."))&IF(AR9=0,"",IF(AR9="",""," ФССП присвоил "&AR9&" уровень риска для данного ПКО.")))) -> ООО ПКО «РСВ» зарегистрировано по адресу: 127055, Москва, Бутырский Вал, дом № 68/70, стр. 1, этаж 2, помещение I, комната №4. Генеральным директором является Медведева Ольга Владимировна. Рост доходов компании за 5 лет: 566,9%. Рост финансовых активов компании за 5 лет: 402,04%. Объем заемных средств компании на конец 2024 года: 3181681 тыс. руб. ФССП присвоил Высокий уровень риска для данного ПКО.
